Workbook
Name Slicer_Month: #N/A
Name Slicer_Region: #N/A
Name Slicer_Sub_Category: #N/A
Name Slicer_Year: #N/A

Sheet Sheet1
A1: Order ID | B1: Order Date | C1: Ship Date | D1: Ship Mode | E1: Customer ID | F1: Customer Name | G1: Segment | H1: Country | I1: City | J1: State | K1: Region | L1: Product ID | M1: Category | N1: Sub-Category | O1: Product Name | P1: Sales | Q1: Quantity | R1: Profit | S1: Duration | T1: Month
A2: CA-2016-152156 | B2: 42682 | C2: 42685 | D2: Second Class | E2: CG-12520 | F2: Claire Gute | G2: Consumer | H2: United States | I2: Henderson | J2: Kentucky | K2: South | L2: FUR-BO-10001798 | M2: Furniture | N2: Bookcases | O2: Bush Somerset Collection Bookcase | P2: 261.96 | Q2: 2 | R2: 41.9136 | S2: 3- days | T2: Nov
A3: CA-2016-152156 | B3: 42682 | C3: 42685 | D3: Second Class | E3: CG-12520 | F3: Claire Gute | G3: Consumer | H3: United States | I3: Henderson | J3: Kentucky | K3: South | L3: FUR-CH-10000454 | M3: Furniture | N3: Chairs | O3: Hon Deluxe Fabric Upholstered Stacking Chairs, Rounded Back | P3: 731.94 | Q3: 3 | R3: 219.582 | S3: 3- days | T3: Nov
A4: US-2015-108966 | B4: 42288 | C4: 42295 | D4: Standard Class | E4: SO-20335 | F4: Sean O'Donnell | G4: Consumer | H4: United States | I4: Fort Lauderdale | J4: Florida | K4: South | L4: FUR-TA-10000577 | M4: Furniture | N4: Tables | O4: Bretford CR4500 Series Slim Rectangular Table | P4: 957.5775 | Q4: 5 | R4: -383.031 | S4: 7- days | T4: Oct
A5: CA-2014-115812 | B5: 41799 | C5: 41804 | D5: Standard Class | E5: BH-11710 | F5: Brosina Hoffman | G5: Consumer | H5: United States | I5: Los Angeles | J5: California | K5: West | L5: FUR-FU-10001487 | M5: Furniture | N5: Furnishings | O5: Eldon Expressions Wood and Plastic Desk Accessories, Cherry Wood | P5: 48.86 | Q5: 7 | R5: 14.1694 | S5: 5- days | T5: Jun
A6: CA-2014-115812 | B6: 41799 | C6: 41804 | D6: Standard Class | E6: BH-11710 | F6: Brosina Hoffman | G6: Consumer | H6: United States | I6: Los Angeles | J6: California | K6: West | L6: FUR-TA-10001539 | M6: Furniture | N6: Tables | O6: Chromcraft Rectangular Conference Tables | P6: 1706.184 | Q6: 9 | R6: 85.3092 | S6: 5- days | T6: Jun
A7: US-2017-156909 | B7: 42932 | C7: 42934 | D7: Second Class | E7: SF-20065 | F7: Sandra Flanagan | G7: Consumer | H7: United States | I7: Philadelphia | J7: Pennsylvania | K7: East | L7: FUR-CH-10002774 | M7: Furniture | N7: Chairs | O7: Global Deluxe Stacking Chair, Gray | P7: 71.372 | Q7: 2 | R7: -1.0196 | S7: 2- days | T7: Jul
A8: CA-2015-106320 | B8: 42272 | C8: 42277 | D8: Standard Class | E8: EB-13870 | F8: Emily Burns | G8: Consumer | H8: United States | I8: Orem | J8: Utah | K8: West | L8: FUR-TA-10000577 | M8: Furniture | N8: Tables | O8: Bretford CR4500 Series Slim Rectangular Table | P8: 1044.63 | Q8: 3 | R8: 240.2649 | S8: 5- days | T8: Sep
A9: US-2015-150630 | B9: 42264 | C9: 42268 | D9: Standard Class | E9: TB-21520 | F9: Tracy Blumstein | G9: Consumer | H9: United States | I9: Philadelphia | J9: Pennsylvania | K9: East | L9: FUR-BO-10004834 | M9: Furniture | N9: Bookcases | O9: Riverside Palais Royal Lawyers Bookcase, Royale Cherry Finish | P9: 3083.43 | Q9: 7 | R9: -1665.0522 | S9: 4- days | T9: Sep
A10: US-2015-150630 | B10: 42264 | C10: 42268 | D10: Standard Class | E10: TB-21520 | F10: Tracy Blumstein | G10: Consumer | H10: United States | I10: Philadelphia | J10: Pennsylvania | K10: East | L10: FUR-FU-10004848 | M10: Furniture | N10: Furnishings | O10: Howard Miller 13-3/4" Diameter Brushed Chrome Round Wall Clock | P10: 124.2 | Q10: 3 | R10: 15.525 | S10: 4- days | T10: Sep
A11: CA-2016-117590 | B11: 42712 | C11: 42714 | D11: First Class | E11: GH-14485 | F11: Gene Hale | G11: Corporate | H11: United States | I11: Richardson | J11: Texas | K11: Central | L11: FUR-FU-10003664 | M11: Furniture | N11: Furnishings | O11: Electrix Architect's Clamp-On Swing Arm Lamp, Black | P11: 190.92 | Q11: 5 | R11: -147.963 | S11: 2- days | T11: Dec
A12: CA-2015-117415 | B12: 42365 | C12: 42369 | D12: Standard Class | E12: SN-20710 | F12: Steve Nguyen | G12: Home Office | H12: United States | I12: Houston | J12: Texas | K12: Central | L12: FUR-BO-10002545 | M12: Furniture | N12: Bookcases | O12: Atlantic Metals Mobile 3-Shelf Bookcases, Custom Colors | P12: 532.3992 | Q12: 3 | R12: -46.9764 | S12: 4- days | T12: Dec
A13: CA-2015-117415 | B13: 42365 | C13: 42369 | D13: Standard Class | E13: SN-20710 | F13: Steve Nguyen | G13: Home Office | H13: United States | I13: Houston | J13: Texas | K13: Central | L13: FUR-CH-10004218 | M13: Furniture | N13: Chairs | O13: Global Fabric Manager's Chair, Dark Gray | P13: 212.058 | Q13: 3 | R13: -15.147 | S13: 4- days | T13: Dec
... A2122: CA-2017-121258 | B2122: 42792 | C2122: 42797 | D2122: Standard Class | E2122: DB-13060 | F2122: Dave Brooks | G2122: Consumer | H2122: United States | I2122: Costa Mesa | J2122: California | K2122: West | L2122: FUR-FU-10000747 | M2122: Furniture | N2122: Furnishings | O2122: Tenex B1-RE Series Chair Mats for Low Pile Carpets | P2122: 91.96 | Q2122: 2 | R2122: 15.6332 | S2122: 5- days | T2122: Feb

Sheet Table1
A1: Order ID | B1: Order Date | C1: Year | D1: Ship Date | E1: Ship Mode | F1: Customer ID | G1: Customer Name | H1: Segment | I1: Country | J1: City | K1: State | L1: Region | M1: Product ID | N1: Category | O1: Sub-Category | P1: Product Name | Q1: Sales | R1: Quantity | S1: Profit | T1: Profit Margin | U1: Duration | V1: Month
A2: CA-2017-155642 | B2: 42873 | C2: =TEXT(Table1_2[[#This Row],[Order Date]], "yyyy") -> 2017 | D2: 42877 | E2: Standard Class | F2: BM-11575 | G2: Brendan Murry | H2: Corporate | I2: United States | J2: Chicago | K2: Illinois | L2: Central | M2: FUR-FU-10001918 | N2: Furniture | O2: Furnishings | P2: C-Line Cubicle Keepers Polyproplyene Holder With Velcro Backings | Q2: 1.892 | R2: 1 | S2: -0.9933 | T2: =Table1_2[[#This Row],[Profit]] / Table1_2[[#This Row],[Sales]] -> -0.525 | U2: 4- days | V2: May
A3: CA-2017-160045 | B3: 42851 | C3: =TEXT(Table1_2[[#This Row],[Order Date]], "yyyy") -> 2017 | D3: 42852 | E3: First Class | F3: LB-16735 | G3: Larry Blacks | H3: Consumer | I3: United States | J3: Fort Worth | K3: Texas | L3: Central | M3: FUR-FU-10000010 | N3: Furniture | O3: Furnishings | P3: DAX Value U-Channel Document Frames, Easel Back | Q3: 1.988 | R3: 1 | S3: -1.4413 | T3: =Table1_2[[#This Row],[Profit]] / Table1_2[[#This Row],[Sales]] -> -0.725 | U3: 1- days | V3: Apr | Y3: =MEDIAN(T2:T2120) -> 0.11111111
A4: CA-2017-122595 | B4: 43083 | C4: =TEXT(Table1_2[[#This Row],[Order Date]], "yyyy") -> 2017 | D4: 43089 | E4: Standard Class | F4: GM-14455 | G4: Gary Mitchum | H4: Home Office | I4: United States | J4: Chicago | K4: Illinois | L4: Central | M4: FUR-FU-10002963 | N4: Furniture | O4: Furnishings | P4: Master Caster Door Stop, Gray | Q4: 2.032 | R4: 1 | S4: -1.3208 | T4: =Table1_2[[#This Row],[Profit]] / Table1_2[[#This Row],[Sales]] -> -0.65 | U4: 6- days | V4: Dec
A5: US-2016-110156 | B5: 42693 | C5: =TEXT(Table1_2[[#This Row],[Order Date]], "yyyy") -> 2016 | D5: 42698 | E5: Standard Class | F5: EH-13945 | G5: Eric Hoffmann | H5: Consumer | I5: United States | J5: Houston | K5: Texas | L5: Central | M5: FUR-FU-10000206 | N5: Furniture | O5: Furnishings | P5: GE General Purpose, Extra Long Life, Showcase & Floodlight Incandescent Bulbs | Q5: 2.328 | R5: 2 | S5: -0.7566 | T5: =Table1_2[[#This Row],[Profit]] / Table1_2[[#This Row],[Sales]] -> -0.325 | U5: 5- days | V5: Nov | Y5: =AVERAGE(T2:T2120) -> 0.038907781
A6: CA-2016-132829 | B6: 42727 | C6: =TEXT(Table1_2[[#This Row],[Order Date]], "yyyy") -> 2016 | D6: 42730 | E6: Second Class | F6: LA-16780 | G6: Laura Armstrong | H6: Corporate | I6: United States | J6: Houston | K6: Texas | L6: Central | M6: FUR-FU-10000206 | N6: Furniture | O6: Furnishings | P6: GE General Purpose, Extra Long Life, Showcase & Floodlight Incandescent Bulbs | Q6: 2.328 | R6: 2 | S6: -0.7566 | T6: =Table1_2[[#This Row],[Profit]] / Table1_2[[#This Row],[Sales]] -> -0.325 | U6: 3- days | V6: Dec
A7: CA-2017-129021 | B7: 42970 | C7: =TEXT(Table1_2[[#This Row],[Order Date]], "yyyy") -> 2017 | D7: 42973 | E7: Second Class | F7: PO-18850 | G7: Patrick O'Brill | H7: Consumer | I7: United States | J7: Tallahassee | K7: Florida | L7: South | M7: FUR-FU-10001852 | N7: Furniture | O7: Furnishings | P7: Eldon Regeneration Recycled Desk Accessories, Smoke | Q7: 2.784 | R7: 2 | S7: 0.4176 | T7: =Table1_2[[#This Row],[Profit]] / Table1_2[[#This Row],[Sales]] -> 0.15 | U7: 3- days | V7: Aug
A8: CA-2017-154214 | B8: 42814 | C8: =TEXT(Table1_2[[#This Row],[Order Date]], "yyyy") -> 2017 | D8: 42819 | E8: Second Class | F8: TB-21595 | G8: Troy Blackwell | H8: Consumer | I8: United States | J8: Columbus | K8: Indiana | L8: Central | M8: FUR-FU-10000206 | N8: Furniture | O8: Furnishings | P8: GE General Purpose, Extra Long Life, Showcase & Floodlight Incandescent Bulbs | Q8: 2.91 | R8: 1 | S8: 1.3677 | T8: =Table1_2[[#This Row],[Profit]] / Table1_2[[#This Row],[Sales]] -> 0.47 | U8: 5- days | V8: Mar
A9: CA-2017-163860 | B9: 43097 | C9: =TEXT(Table1_2[[#This Row],[Order Date]], "yyyy") -> 2017 | D9: 43101 | E9: Standard Class | F9: LO-17170 | G9: Lori Olson | H9: Corporate | I9: United States | J9: Peoria | K9: Illinois | L9: Central | M9: FUR-FU-10001935 | N9: Furniture | O9: Furnishings | P9: 3M Hangers With Command Adhesive | Q9: 2.96 | R9: 2 | S9: -1.406 | T9: =Table1_2[[#This Row],[Profit]] / Table1_2[[#This Row],[Sales]] -> -0.475 | U9: 4- days | V9: Dec
A10: CA-2015-122756 | B10: 42341 | C10: =TEXT(Table1_2[[#This Row],[Order Date]], "yyyy") -> 2015 | D10: 42345 | E10: Standard Class | F10: DK-13225 | G10: Dean Katz | H10: Corporate | I10: United States | J10: Philadelphia | K10: Pennsylvania | L10: East | M10: FUR-FU-10001935 | N10: Furniture | O10: Furnishings | P10: 3M Hangers With Command Adhesive | Q10: 2.96 | R10: 1 | S10: 0.777 | T10: =Table1_2[[#This Row],[Profit]] / Table1_2[[#This Row],[Sales]] -> 0.2625 | U10: 4- days | V10: Dec
A11: CA-2017-127782 | B11: 43041 | C11: =TEXT(Table1_2[[#This Row],[Order Date]], "yyyy") -> 2017 | D11: 43045 | E11: Standard Class | F11: TH-21115 | G11: Thea Hudgings | H11: Corporate | I11: United States | J11: Philadelphia | K11: Pennsylvania | L11: East | M11: FUR-FU-10001847 | N11: Furniture | O11: Furnishings | P11: Eldon Image Series Black Desk Accessories | Q11: 3.312 | R11: 1 | S11: 0.6624 | T11: =Table1_2[[#This Row],[Profit]] / Table1_2[[#This Row],[Sales]] -> 0.2 | U11: 4- days | V11: Nov
A12: CA-2014-106264 | B12: 41999 | C12: =TEXT(Table1_2[[#This Row],[Order Date]], "yyyy") -> 2014 | D12: 42003 | E12: Standard Class | F12: CK-12595 | G12: Clytie Kelty | H12: Consumer | I12: United States | J12: San Diego | K12: California | L12: West | M12: FUR-FU-10001852 | N12: Furniture | O12: Furnishings | P12: Eldon Regeneration Recycled Desk Accessories, Smoke | Q12: 3.48 | R12: 2 | S12: 1.1136 | T12: =Table1_2[[#This Row],[Profit]] / Table1_2[[#This Row],[Sales]] -> 0.32 | U12: 4- days | V12: Dec
A13: CA-2017-118773 | B13: 42775 | C13: =TEXT(Table1_2[[#This Row],[Order Date]], "yyyy") -> 2017 | D13: 42780 | E13: Standard Class | F13: TP-21415 | G13: Tom Prescott | H13: Consumer | I13: United States | J13: Houston | K13: Texas | L13: Central | M13: FUR-FU-10000550 | N13: Furniture | O13: Furnishings | P13: Stacking Trays by OIC | Q13: 3.984 | R13: 2 | S13: -2.6892 | T13: =Table1_2[[#This Row],[Profit]] / Table1_2[[#This Row],[Sales]] -> -0.675 | U13: 5- days | V13: Feb
A14: CA-2014-138317 | B14: 41811 | C14: =TEXT(Table1_2[[#This Row],[Order Date]], "yyyy") -> 2014 | D14: 41815 | E14: Standard Class | F14: NW-18400 | G14: Natalie Webber | H14: Consumer | I14: United States | J14: Philadelphia | K14: Pennsylvania | L14: East | M14: FUR-FU-10000550 | N14: Furniture | O14: Furnishings | P14: Stacking Trays by OIC | Q14: 3.984 | R14: 1 | S14: 0.6474 | T14: =Table1_2[[#This Row],[Profit]] / Table1_2[[#This Row],[Sales]] -> 0.1625 | U14: 4- days | V14: Jun
A15: CA-2016-157749 | B15: 42525 | C15: =TEXT(Table1_2[[#This Row],[Order Date]], "yyyy") -> 2016 | D15: 42530 | E15: Second Class | F15: KL-16645 | G15: Ken Lonsdale | H15: Consumer | I15: United States | J15: Chicago | K15: Illinois | L15: Central | M15: FUR-FU-10002505 | N15: Furniture | O15: Furnishings | P15: Eldon 100 Class Desk Accessories | Q15: 4.044 | R15: 3 | S15: -2.8308 | T15: =Table1_2[[#This Row],[Profit]] / Table1_2[[#This Row],[Sales]] -> -0.7 | U15: 5- days | V15: Jun
A16: CA-2015-121188 | B16: 42244 | C16: =TEXT(Table1_2[[#This Row],[Order Date]], "yyyy") -> 2015 | D16: 42251 | E16: Standard Class | F16: CB-12025 | G16: Cassandra Brandow | H16: Consumer | I16: United States | J16: Los Angeles | K16: California | L16: West | M16: FUR-FU-10003981 | N16: Furniture | O16: Furnishings | P16: Eldon Wave Desk Accessories | Q16: 4.16 | R16: 2 | S16: 1.7472 | T16: =Table1_2[[#This Row],[Profit]] / Table1_2[[#This Row],[Sales]] -> 0.42 | U16: 7- days | V16: Aug
A17: CA-2016-149461 | B17: 42687 | C17: =TEXT(Table1_2[[#This Row],[Order Date]], "yyyy") -> 2016 | D17: 42693 | E17: Standard Class | F17: AS-10135 | G17: Adrian Shami | H17: Home Office | I17: United States | J17: Auburn | K17: Washington | L17: West | M17: FUR-FU-10004270 | N17: Furniture | O17: Furnishings | P17: Eldon Image Series Desk Accessories, Burgundy | Q17: 4.18 | R17: 1 | S17: 1.5048 | T17: =Table1_2[[#This Row],[Profit]] / Table1_2[[#This Row],[Sales]] -> 0.36 | U17: 6- days | V17: Nov
... A2121: CA-2017-118892 | B2121: 42964 | C2121: =TEXT(Table1_2[[#This Row],[Order Date]], "yyyy") -> 2017 | D2121: 42969 | E2121: Second Class | F2121: TP-21415 | G2121: Tom Prescott | H2121: Consumer | I2121: United States | J2121: Philadelphia | K2121: Pennsylvania | L2121: East | M2121: FUR-CH-10002024 | N2121: Furniture | O2121: Chairs | P2121: HON 5400 Series Task Chairs for Big and Tall | Q2121: 4416.174 | R2121: 9 | S2121: -630.882 | T2121: =Table1_2[[#This Row],[Profit]] / Table1_2[[#This Row],[Sales]] -> -0.14285714 | U2121: 5- days | V2121: Aug

Sheet Pivot Chart
A1: Profit Margin | B1: =D5 / E5 -> 0.024866951 | C1: =D5 / E5 -> 0.024866951 | H1: MONTHLY SALES TREND | R1: SALES, QUANTITY AND PROFIT TRENDS OVER TIME | AG1: 18451.273 | AH1: 741999.8
E2: 18451.273 | F2: 8028 | H2: Row Labels | I2: Sum of Sales | R2: Row Labels | S2: Sum of Sales | T2: Sum of Quantity | U2: Sum of Profit | AF2: Profit Margin | AG2: =AG1 / AH1 -> 0.024866951
A3: Sum of Sales | B3: Sum of Quantity | C3: Sum of Profit | E3: 18451.273 | F3: 8028 | H3: Jan | I3: 31569.242 | R3: Jan | S3: 31569.242 | T3: 345 | U3: -1944.213
A4: 741999.8 | B4: 8028 | C4: 18451.273 | H4: Feb | I4: 15765.92 | R4: Feb | S4: 15765.92 | T4: 208 | U4: 693.5796 | AF4: Average of Sales | AG4: Sum of Quantity | AH4: Average of Profit
D5: 18451.273 | E5: 741999.8 | H5: Mar | I5: 50768.276 | R5: Mar | S5: 50768.276 | T5: 527 | U5: 771.9875 | AF5: 349.83489 | AG5: 8028 | AH5: 8.6993271
H6: Apr | I6: 40698.584 | R6: Apr | S6: 40698.584 | T6: 509 | U6: 1460.3261 | AG6: 8.6993271 | AH6: 349.83489 | AJ6: Median Profit
A7: Row Labels | B7: Sum of Sales | C7: Sum of Quantity | D7: Sum of Profit | E7: Count of Product ID | H7: May | I7: 48365.131 | R7: May | S7: 48365.131 | T7: 588 | U7: 2302.2981
A8: 2014 | B8: 157192.85 | C8: 1623 | D8: 5457.7255 | E8: 421 | H8: Jun | I8: 52999.463 | R8: Jun | S8: 52999.463 | T8: 538 | U8: 982.3847 | AF8: Average Profit Margin | AG8: 0.038907781
A9: 2015 | B9: 170518.24 | C9: 1775 | D9: 3015.2029 | E9: 452 | H9: Jul | I9: 49377.012 | R9: Jul | S9: 49377.012 | T9: 618 | U9: 1412.6846 | AF9: Median Profit Margin | AI9: 0.11111111
A10: 2016 | B10: 198901.44 | C10: 2193 | D10: 6959.9531 | E10: 562 | H10: Aug | I10: 44884.045 | R10: Aug | S10: 44884.045 | T10: 461 | U10: 4.0941
A11: 2017 | B11: 215387.27 | C11: 2437 | D11: 3018.3913 | E11: 686 | H11: Sep | I11: 106380.59 | R11: Sep | S11: 106380.59 | T11: 999 | U11: 5460.0023
A12: Grand Total | B12: 741999.8 | C12: 8028 | D12: 18451.273 | E12: 2121 | H12: Oct | I12: 58087.516 | R12: Oct | S12: 58087.516 | T12: 709 | U12: -3027.9321
H13: Nov | I13: 121286.05 | R13: Nov | S13: 121286.05 | T13: 1220 | U13: 3920.0007
H14: Dec | I14: 121817.97 | R14: Dec | S14: 121817.97 | T14: 1306 | U14: 6416.0602
B15: CY | C15: PY | D15: YOY % | E15: ICON | H15: Grand Total | I15: 741999.8 | R15: Grand Total | S15: 741999.8 | T15: 8028 | U15: 18451.273
A16: SALES | B16: 215387.27 | C16: 198901.44 | D16: =(B16 - C16) / C16 -> 0.082884435 | E16: =IF(D16>0,"▲","▼")& TEXT(ABS(D16),"0.00%")& " " &"YOY" -> ▲8.29% YOY
A17: QUANTITY | B17: 2437 | C17: 2193 | D17: =(B17 - C17) / C17 -> 0.11126311 | E17: =IF(D17>0,"▲","▼")& TEXT(ABS(D17),"0.00%")& " " &"YOY" -> ▲11.13% YOY
A18: PROFIT | B18: 3018.3913 | C18: 6959.9531 | D18: =(B18 -C18) / C18 -> -0.56632017 | E18: =IF(D18>0,"▲","▼")& TEXT(ABS(D18),"0.00%")& " " &"YOY" -> ▼56.63% YOY | AF18: Row Labels | AG18: Sum of Profit | AH18: Sum of Quantity
A19: PRODUCT | B19: 686 | C19: 562 | D19: =(B19 -C19) / C19 -> 0.22064057 | E19: =IF(D19>0,"▲","▼")& TEXT(ABS(D19),"0.00%")& " " &"YOY" -> ▲22.06% YOY | H19: MONTHLY PROFIT TREND | AF19: First Class | AG19: 3066.9474 | AH19: 1238
H20: Row Labels | I20: Sum of Profit | AF20: Same Day | AG20: 797.3484 | AH20: 453
A21: HIGHEST SALES BY SUBCATEGORY | H21: Jan | I21: -1944.213 | T21: Row Labels | U21: Sum of Profit | AF21: Second Class | AG21: 4226.2614 | AH21: 1569
A22: Row Labels | B22: Sum of Sales | H22: Feb | I22: 693.5796 | T22: Central | U22: -2871.0494 | AF22: Standard Class | AG22: 10360.716 | AH22: 4768
A23: Bookcases | B23: 114880 | H23: Mar | I23: 771.9875 | T23: Consumer | U23: -3994.4342 | AF23: Grand Total | AG23: 18451.273 | AH23: 8028
A24: Chairs | B24: 328449.1 | H24: Apr | I24: 1460.3261 | T24: Corporate | U24: 2321.9939
A25: Furnishings | B25: 91705.164 | H25: May | I25: 2302.2981 | T25: Home Office | U25: -1198.6091
A26: Tables | B26: 206965.53 | H26: Jun | I26: 982.3847 | T26: East | U26: 3046.1658
A27: Grand Total | B27: 741999.8 | H27: Jul | I27: 1412.6846 | T27: Consumer | U27: 2038.1122
H28: Aug | I28: 4.0941 | T28: Corporate | U28: 342.1257
H29: Sep | I29: 5460.0023 | T29: Home Office | U29: 665.9279
H30: Oct | I30: -3027.9321 | T30: South | U30: 6771.2061
H31: Nov | I31: 3920.0007 | T31: Consumer | U31: 4616.7326
H32: Dec | I32: 6416.0602 | T32: Corporate | U32: 952.0303
H33: Grand Total | I33: 18451.273 | T33: Home Office | U33: 1202.4432
T34: West | U34: 11504.95
T35: Consumer | U35: 4330.668
T36: Corporate | U36: 3968.6659
T37: Home Office | U37: 3205.6164
K38: Row Labels | L38: Sum of Profit | T38: Grand Total | U38: 18451.273
A39: TOP SELING CITIES | K39: Bookcases | L39: -3472.556
A40: Row Labels | B40: Sum of Sales | K40: Chairs | L40: 26590.166
...

Sheet Map
A1: State | B1: Sales
A2: ='Pivot Chart'!A56 -> Alabama | B2: ='Pivot Chart'!B56 -> 6332.48
A3: ='Pivot Chart'!A57 -> Arizona | B3: ='Pivot Chart'!B57 -> 13525.291
A4: ='Pivot Chart'!A58 -> Arkansas | B4: ='Pivot Chart'!B58 -> 3187.55
A5: ='Pivot Chart'!A59 -> California | B5: ='Pivot Chart'!B59 -> 156064.6
A6: ='Pivot Chart'!A60 -> Colorado | B6: ='Pivot Chart'!B60 -> 13243.037
A7: ='Pivot Chart'!A61 -> Connecticut | B7: ='Pivot Chart'!B61 -> 5174.987
A8: ='Pivot Chart'!A62 -> Delaware | B8: ='Pivot Chart'!B62 -> 4759.319
A9: ='Pivot Chart'!A63 -> District of Columbia | B9: ='Pivot Chart'!B63 -> 1346.58
A10: ='Pivot Chart'!A64 -> Florida | B10: ='Pivot Chart'!B64 -> 22987.038
A11: ='Pivot Chart'!A65 -> Georgia | B11: ='Pivot Chart'!B65 -> 8321.48
A12: ='Pivot Chart'!A66 -> Idaho | B12: ='Pivot Chart'!B66 -> 2595.482
A13: ='Pivot Chart'!A67 -> Illinois | B13: ='Pivot Chart'!B67 -> 28274.522
... A49: ='Pivot Chart'!A103 -> Wyoming | B49: ='Pivot Chart'!B103 -> 1603.136

Sheet Map 2
A1: State | B1: Profit
A2: ='Pivot Chart'!E58 -> Alabama | B2: ='Pivot Chart'!F58 -> 1231.3882
A3: ='Pivot Chart'!E59 -> Arizona | B3: ='Pivot Chart'!F59 -> -2744.9228
A4: ='Pivot Chart'!E60 -> Arkansas | B4: ='Pivot Chart'!F60 -> 781.4552
A5: ='Pivot Chart'!E61 -> California | B5: ='Pivot Chart'!F61 -> 9162.9656
A6: ='Pivot Chart'!E62 -> Colorado | B6: ='Pivot Chart'!F62 -> -2683.1342
A7: ='Pivot Chart'!E63 -> Connecticut | B7: ='Pivot Chart'!F63 -> 1226.2805
A8: ='Pivot Chart'!E64 -> Delaware | B8: ='Pivot Chart'!F64 -> 870.7072
A9: ='Pivot Chart'!E65 -> District of Columbia | B9: ='Pivot Chart'!F65 -> 350.0835
A10: ='Pivot Chart'!E66 -> Florida | B10: ='Pivot Chart'!F66 -> -2254.9807
A11: ='Pivot Chart'!E67 -> Georgia | B11: ='Pivot Chart'!F67 -> 2049.458
A12: ='Pivot Chart'!E68 -> Idaho | B12: ='Pivot Chart'!F68 -> 533.9665
A13: ='Pivot Chart'!E69 -> Illinois | B13: ='Pivot Chart'!F69 -> -9076.2894
... A49: ='Pivot Chart'!E105 -> Wyoming | B49: ='Pivot Chart'!F105 -> 100.196

Sheet  Dashboard 1

Sheet Dashboard 2
